<mujoco model="pendulum">
	<compiler angle="radian" inertiafromgeom="true"/>

	<default>
		<joint armature="1" damping="1" limited="true"/>
		<geom contype="0" friction="1 0.1 0.1" rgba="0.7 0.7 0 1"/>
	</default>

	<option gravity="0 0 -9.81" integrator="RK4" timestep="0.01"/>
  
	<worldbody> 
		<!--visulize x,y,and z axes-->
		<site name="x_axes" pos="0.1 0 0" size="0.1 0.001 0.001" rgba="1 0 0 0.2"  type="box"></site>
		<site name="y_axes" pos="0 0.1 0" size="0.001 0.1 0.001" rgba="0 1 0 0.2" type="box"></site>
		<site name="z_axes" pos="0 0 0.1" size="0.001 0.001 0.1" rgba="0 0 1 0.2" type="box"></site> 
		<site name="wall" rgba="0.5 0.5 0.5 1" pos="-0.01 0 0" size=".001 0.7 0.7" type="box"></site> 
		<site name="floor" rgba="0.5 0.5 0.5 1" pos="0 0 -0.7" size="0.7 0.7 .001" type="box"></site>  
  
		<body name="body" pos="0 0 0" >
			<geom name="root" conaffinity="0" contype="0" pos="0 0 0" quat="0.5 0.5 -0.5 -0.5" rgba="0.9 0.4 0.6 1" size=".011 0.02"  type="cylinder"/>
			<geom name="link" fromto="0 0.5 0 0 0 0"  rgba="0.0 0.4 0.6 1" size=".01" type="capsule"/>
			<joint name="joint" axis="1 0 0" limited="false" range="-3.141592 3.141592" pos="0 0 0" type="hinge" frictionloss="1"/> 
		</body>

		<light diffuse=".8 .8 .8" dir="0 -.15 -1" directional="false" pos="1 1 4.0" specular="0.3 0.3 0.3" castshadow="false"/>
		<light diffuse=".8 .8 .8" dir="0 -.15 -1" directional="false" pos="-3. -3. 4.0" specular="0.3 0.3 0.3" castshadow="false"/>
    	<camera mode="fixed" name="frontview" pos="2.6 0 0" quat="0.5 0.5 0.5 0.5"/>
	</worldbody>

	<actuator>
		<motor name="motor" ctrllimited="true" ctrlrange="-1.0 1.0" gear="5.0" joint="joint"/> 
	</actuator>
	

</mujoco>